e<?xml version="1.0" ?>
<!-- =================================================================================== -->
<!-- |    This document was autogenerated by xacro from /root/doosan_robot/src/doosan-robot2/dsr_description2/xacro/m1013_hande.urdf.xacro | -->
<!-- |    EDITING THIS FILE BY HAND IS NOT RECOMMENDED                                 | -->
<!-- =================================================================================== -->
<robot name="m1013_hande">
  <!-- -pi/2 -->
  <!--
    Original URDF file by Cristian C Beltran-Hernandez
  -->
  <ros2_control name="robotiq_hande_gripper" type="system">
    <hardware>
      <plugin>mock_components/GenericSystem</plugin>
    </hardware>
    <!-- The right finger joint uses the mimic feature -->
    <joint name="robotiq_hande_left_finger_joint">
      <command_interface name="position">
        <param name="min">0</param>
        <param name="max">0.025</param>
      </command_interface>
      <state_interface name="position">
        <param name="initial_value">0.025</param>
      </state_interface>
      <state_interface name="velocity">
        <param name="initial_value">0</param>
      </state_interface>
    </joint>
  </ros2_control>
  <!-- Robotiq Hand-E specs -->
  <!--  + Height added by the IO coupler: 11.0mm -->
  <!--  + Height added by the Hand-E: 99.0mm -->
  <!--  + Coupler mass includes the bolts -->
  <joint name="robotiq_hande_coupler_joint" type="fixed">
    <origin rpy="0 0 0" xyz="0 0 0"/>
    <parent link="link_6"/>
    <child link="robotiq_hande_coupler"/>
  </joint>
  <link name="robotiq_hande_coupler">
    <visual>
      <geometry>
        <mesh filename="package://robotiq_hande_description/meshes/io_coupler.dae"/>
      </geometry>
    </visual>
    <collision>
      <origin rpy="0 0 0" xyz="0 0 0.005449999999999999"/>
      <geometry>
        <cylinder length="0.0169" radius="0.0385"/>
      </geometry>
    </collision>
    <inertial>
      <mass value="0.119"/>
      <origin rpy="0 0 0" xyz="0 0 0.005449999999999999"/>
      <inertia ixx="4.4668218799372e-05" ixy="0.0" ixz="0.0" iyy="4.4668218799372e-05" iyz="0.0" izz="8.367187499999999e-05"/>
    </inertial>
  </link>
  <joint name="robotiq_hande_base_joint" type="fixed">
    <origin rpy="0 0 0" xyz="0 0 0.011"/>
    <parent link="robotiq_hande_coupler"/>
    <child link="robotiq_hande_link"/>
  </joint>
  <link name="robotiq_hande_link">
    <visual>
      <origin rpy="0 0 0" xyz="0 0 0"/>
      <geometry>
        <mesh filename="package://robotiq_hande_description/meshes/hande.dae" scale="1.0 1.0 1.0"/>
      </geometry>
    </visual>
    <collision>
      <origin rpy="0 0 0" xyz="0 0 0.053450000000000004"/>
      <geometry>
        <cylinder length="0.10690000000000001" radius="0.0385"/>
      </geometry>
    </collision>
    <inertial>
      <mass value="0.86387"/>
      <origin rpy="0 0 0" xyz="0 0 0.0495"/>
      <inertia ixx="0.0010092697156669523" ixy="0.0" ixz="0.0" iyy="0.0010092697156669523" iyz="0.0" izz="0.00060740859375"/>
    </inertial>
  </link>
  <joint name="robotiq_hande_left_finger_joint" type="prismatic">
    <origin rpy="0 0 0" xyz="0 0 0.099"/>
    <parent link="robotiq_hande_link"/>
    <child link="robotiq_hande_left_finger"/>
    <axis xyz="1 0 0"/>
    <limit effort="130" lower="0" upper="0.025" velocity="0.15"/>
  </joint>
  <link name="robotiq_hande_left_finger">
    <visual>
      <origin rpy="0 0 0" xyz="0 0 0"/>
      <geometry>
        <mesh filename="package://robotiq_hande_description/meshes/finger.dae" scale="1.0 1.0 1.0"/>
      </geometry>
    </visual>
    <collision>
      <origin rpy="0 0 0" xyz="0 0 0"/>
      <geometry>
        <mesh filename="package://robotiq_hande_description/meshes/finger_collision.dae" scale="1.0 1.0 1.0"/>
      </geometry>
    </collision>
    <inertial>
      <origin rpy="0 0 0" xyz="0 0 0"/>
      <mass value="0.03804"/>
      <inertia ixx="1E-9" ixy="0.0" ixz="0.0" iyy="1E-9" iyz="0.0" izz="1E-9"/>
    </inertial>
  </link>
  <joint name="robotiq_hande_right_finger_joint" type="prismatic">
    <origin rpy="0 0 0" xyz="0 0 0.099"/>
    <parent link="robotiq_hande_link"/>
    <child link="robotiq_hande_right_finger"/>
    <axis xyz="-1 0 0"/>
    <limit effort="130" lower="0" upper="0.025" velocity="0.15"/>
    <mimic joint="robotiq_hande_left_finger_joint" multiplier="1" offset="0"/>
  </joint>
  <link name="robotiq_hande_right_finger">
    <visual>
      <origin rpy="0 0 3.141592653589793" xyz="0 0 0"/>
      <geometry>
        <mesh filename="package://robotiq_hande_description/meshes/finger.dae" scale="1.0 1.0 1.0"/>
      </geometry>
    </visual>
    <collision>
      <origin rpy="0 0 3.141592653589793" xyz="0 0 0"/>
      <geometry>
        <mesh filename="package://robotiq_hande_description/meshes/finger_collision.dae" scale="1.0 1.0 1.0"/>
      </geometry>
    </collision>
    <inertial>
      <origin rpy="0 0 0" xyz="0 0 0"/>
      <mass value="0.03804"/>
      <inertia ixx="1E-9" ixy="0.0" ixz="0.0" iyy="1E-9" iyz="0.0" izz="1E-9"/>
    </inertial>
  </link>
  <joint name="robotiq_hande_end_joint" type="fixed">
    <origin rpy="0 0 0" xyz="0 0 0.14550000000000002"/>
    <parent link="robotiq_hande_link"/>
    <child link="robotiq_hande_end"/>
  </joint>
  <link name="robotiq_hande_end"/>
  <!-- ✅ 로봇 본체 생성 -->
  <material name="black">
    <color rgba="0.0 0.0 0.0 1.0"/>
  </material>
  <material name="white">
    <color rgba="1.0 1.0 1.0 1.0"/>
  </material>
  <material name="orange">
    <color rgba="1.0 0.4 0.0 1.0"/>
  </material>
  <material name="dr_gray">
    <color rgba="0.490 0.490 0.486 1.0"/>
  </material>
  <material name="dr_white">
    <color rgba="0.941 0.941 0.941 1.0"/>
  </material>
  <material name="dr_blue">
    <color rgba="0 0 0.15 1"/>
  </material>
  <link name="base_link">
    <inertial>
      <mass value="4.12"/>
      <origin xyz="-3.4e-05   -0.004815    0.048482"/>
      <inertia ixx="0.016331" ixy="-6.4837e-06" ixz="2.0048e-06" iyy="0.014945" iyz="-0.00051686" izz="0.022577"/>
    </inertial>
    <collision>
      <origin rpy="0 0 0" xyz="0 0 0"/>
      <geometry>
        <mesh filename="package://dsr_description2/meshes/m1013_collision/MF1013_0_0.dae" scale="0.001 0.001 0.001"/>
      </geometry>
    </collision>
    <visual>
      <origin rpy="0 0 0" xyz="0 0 0"/>
      <geometry>
        <mesh filename="package://dsr_description2/meshes/m1013_white/MF1013_0_0.dae" scale="0.001 0.001 0.001"/>
      </geometry>
    </visual>
  </link>
  <!-- joint 1 -->
  <joint name="joint_1" type="revolute">
    <parent link="base_link"/>
    <child link="link_1"/>
    <origin rpy="0 0 0" xyz="0 0 0.1525"/>
    <axis xyz="0 0 1"/>
    <limit effort="346" lower="-6.2832" upper="6.2832" velocity="2.0944"/>
    <dynamics friction="0"/>
  </joint>
  <link name="link_1">
    <inertial>
      <mass value="7.8"/>
      <origin xyz="0.000119      0.0428   -0.006383"/>
      <inertia ixx="0.04506" ixy="4.1126e-05" ixz="-5.2533e-05" iyy="0.029679" iyz="-0.0019959" izz="0.047056"/>
    </inertial>
    <collision>
      <origin rpy="0 0 0" xyz="0 0 0"/>
      <geometry>
        <mesh filename="package://dsr_description2/meshes/m1013_collision/MF1013_1_0.dae" scale="0.001 0.001 0.001"/>
      </geometry>
    </collision>
    <visual>
      <origin rpy="0 0 0" xyz="0 0 0"/>
      <geometry>
        <mesh filename="package://dsr_description2/meshes/m1013_white/MF1013_1_0.dae" scale="0.001 0.001 0.001"/>
      </geometry>
    </visual>
  </link>
  <!-- joint2 -->
  <joint name="joint_2" type="revolute">
    <parent link="link_1"/>
    <child link="link_2"/>
    <origin rpy="0 -1.571 -1.571" xyz="0 0.0345 0"/>
    <axis xyz="0 0 1"/>
    <limit effort="346" lower="-6.2832" upper="6.2832" velocity="2.0944"/>
    <dynamics friction="0"/>
  </joint>
  <link name="link_2">
    <inertial>
      <mass value="10.83"/>
      <origin xyz="0.25973    -5.3e-05     0.15782"/>
      <inertia ixx="0.037586" ixy="-0.00036999" ixz="-0.0069927" iyy="0.84943" iyz="4.0201e-05" izz="0.85021"/>
    </inertial>
    <collision>
      <origin rpy="0 0 0" xyz="0 0 0"/>
      <geometry>
        <mesh filename="package://dsr_description2/meshes/m1013_collision/MF1013_2_0.dae" scale="0.001 0.001 0.001"/>
      </geometry>
    </collision>
    <visual>
      <origin rpy="0 0 0" xyz="0 0 0"/>
      <geometry>
        <mesh filename="package://dsr_description2/meshes/m1013_white/MF1013_2_0.dae" scale="0.001 0.001 0.001"/>
      </geometry>
    </visual>
    <collision>
      <origin rpy="0 0 0" xyz="0 0 0"/>
      <geometry>
        <mesh filename="package://dsr_description2/meshes/m1013_collision/MF1013_2_1.dae" scale="0.001 0.001 0.001"/>
      </geometry>
    </collision>
    <visual>
      <origin rpy="0 0 0" xyz="0 0 0"/>
      <geometry>
        <mesh filename="package://dsr_description2/meshes/m1013_white/MF1013_2_1.dae" scale="0.001 0.001 0.001"/>
      </geometry>
    </visual>
    <collision>
      <origin rpy="0 0 0" xyz="0 0 0"/>
      <geometry>
        <mesh filename="package://dsr_description2/meshes/m1013_collision/MF1013_2_2.dae" scale="0.001 0.001 0.001"/>
      </geometry>
    </collision>
    <visual>
      <origin rpy="0 0 0" xyz="0 0 0"/>
      <geometry>
        <mesh filename="package://dsr_description2/meshes/m1013_white/MF1013_2_2.dae" scale="0.001 0.001 0.001"/>
      </geometry>
    </visual>
  </link>
  <!-- joint3 -->
  <joint name="joint_3" type="revolute">
    <parent link="link_2"/>
    <child link="link_3"/>
    <origin rpy="0 0 1.571" xyz="0.62 0 0"/>
    <axis xyz="0 0 1"/>
    <limit effort="163" lower="-2.7925" upper="2.7925" velocity="3.1416"/>
    <dynamics friction="0"/>
  </joint>
  <link name="link_3">
    <inertial>
      <mass value="3.68"/>
      <origin xyz="-1.5e-05   -0.006702    0.044608"/>
      <inertia ixx="0.018748" ixy="7.8071e-06" ixz="-5.0324e-06" iyy="0.018972" iyz="-0.00099342" izz="0.011502"/>
    </inertial>
    <collision>
      <origin rpy="0 0 0" xyz="0 0 0"/>
      <geometry>
        <mesh filename="package://dsr_description2/meshes/m1013_collision/MF1013_3_0.dae" scale="0.001 0.001 0.001"/>
      </geometry>
    </collision>
    <visual>
      <origin rpy="0 0 0" xyz="0 0 0"/>
      <geometry>
        <mesh filename="package://dsr_description2/meshes/m1013_white/MF1013_3_0.dae" scale="0.001 0.001 0.001"/>
      </geometry>
    </visual>
  </link>
  <!-- joint4 -->
  <joint name="joint_4" type="revolute">
    <parent link="link_3"/>
    <child link="link_4"/>
    <origin rpy="1.571 0 0" xyz="0 -0.559 0"/>
    <axis xyz="0 0 1"/>
    <limit effort="50" lower="-6.2832" upper="6.2832" velocity="3.927"/>
    <dynamics friction="0"/>
  </joint>
  <link name="link_4">
    <inertial>
      <mass value="3.82"/>
      <origin xyz="7.1e-05    0.091879    -0.18252"/>
      <inertia ixx="0.19063" ixy="-1.8037e-05" ixz="-3.8576e-05" iyy="0.17268" iyz="-0.052996" izz="0.030386"/>
    </inertial>
    <collision>
      <origin rpy="0 0 0" xyz="0 0 0"/>
      <geometry>
        <mesh filename="package://dsr_description2/meshes/m1013_collision/MF1013_4_0.dae" scale="0.001 0.001 0.001"/>
      </geometry>
    </collision>
    <visual>
      <origin rpy="0 0 0" xyz="0 0 0"/>
      <geometry>
        <mesh filename="package://dsr_description2/meshes/m1013_white/MF1013_4_0.dae" scale="0.001 0.001 0.001"/>
      </geometry>
    </visual>
    <collision>
      <origin rpy="0 0 0" xyz="0 0 0"/>
      <geometry>
        <mesh filename="package://dsr_description2/meshes/m1013_collision/MF1013_4_1.dae" scale="0.001 0.001 0.001"/>
      </geometry>
    </collision>
    <visual>
      <origin rpy="0 0 0" xyz="0 0 0"/>
      <geometry>
        <mesh filename="package://dsr_description2/meshes/m1013_white/MF1013_4_1.dae" scale="0.001 0.001 0.001"/>
      </geometry>
    </visual>
  </link>
  <!-- joint5 -->
  <joint name="joint_5" type="revolute">
    <parent link="link_4"/>
    <child link="link_5"/>
    <origin rpy="-1.571 0 0" xyz="0 0 0"/>
    <axis xyz="0 0 1"/>
    <limit effort="50" lower="-6.2832" upper="6.2832" velocity="3.927"/>
    <dynamics friction="0"/>
  </joint>
  <link name="link_5">
    <inertial>
      <mass value="2.82"/>
      <origin xyz="-0.000273    0.003651    0.032088"/>
      <inertia ixx="0.015583" ixy="2.135e-05" ixz="-5.1895e-06" iyy="0.011519" iyz="0.00042553" izz="0.0088671"/>
    </inertial>
    <collision>
      <origin rpy="0 0 0" xyz="0 0 0"/>
      <geometry>
        <mesh filename="package://dsr_description2/meshes/m1013_collision/MF1013_5_0.dae" scale="0.001 0.001 0.001"/>
      </geometry>
    </collision>
    <visual>
      <origin rpy="0 0 0" xyz="0 0 0"/>
      <geometry>
        <mesh filename="package://dsr_description2/meshes/m1013_white/MF1013_5_0.dae" scale="0.001 0.001 0.001"/>
      </geometry>
    </visual>
  </link>
  <!-- joint6 -->
  <joint name="joint_6" type="revolute">
    <parent link="link_5"/>
    <child link="link_6"/>
    <origin rpy="1.571 0 0" xyz="0 -0.121 0"/>
    <axis xyz="0 0 1"/>
    <limit effort="50" lower="-6.2832" upper="6.2832" velocity="3.927"/>
    <dynamics friction="0"/>
  </joint>
  <link name="link_6">
    <inertial>
      <mass value="1.16"/>
      <origin xyz="-0.000292       7e-06     -0.0539"/>
      <inertia ixx="0.0048282" ixy="4.1298e-06" ixz="6.9879e-06" iyy="0.0059519" iyz="4.252e-06" izz="0.0061263"/>
    </inertial>
    <collision>
      <origin rpy="0 0 0" xyz="0 0 0"/>
      <geometry>
        <mesh filename="package://dsr_description2/meshes/m1013_collision/MF1013_6_0.dae" scale="0.001 0.001 0.001"/>
      </geometry>
    </collision>
    <visual>
      <origin rpy="0 0 0" xyz="0 0 0"/>
      <geometry>
        <mesh filename="package://dsr_description2/meshes/m1013_white/MF1013_6_0.dae" scale="0.001 0.001 0.001"/>
      </geometry>
    </visual>
  </link>
  <!-- Transmission 1 -->
  <transmission name="tran1">
    <type>transmission_interface/SimpleTransmission</type>
    <joint name="joint1">
      <hardwareInterface>hardware_interface/PositionJointInterface</hardwareInterface>
    </joint>
    <actuator name="motor1">
      <hardwareInterface>hardware_interface/PositionJointInterface</hardwareInterface>
      <mechanicalReduction>1</mechanicalReduction>
    </actuator>
  </transmission>
  <!-- Transmission 2 -->
  <transmission name="tran2">
    <type>transmission_interface/SimpleTransmission</type>
    <joint name="joint2">
      <hardwareInterface>hardware_interface/PositionJointInterface</hardwareInterface>
    </joint>
    <actuator name="motor2">
      <hardwareInterface>hardware_interface/PositionJointInterface</hardwareInterface>
      <mechanicalReduction>1</mechanicalReduction>
    </actuator>
  </transmission>
  <!-- Transmission 3 -->
  <transmission name="tran3">
    <type>transmission_interface/SimpleTransmission</type>
    <joint name="joint3">
      <hardwareInterface>hardware_interface/PositionJointInterface</hardwareInterface>
    </joint>
    <actuator name="motor3">
      <hardwareInterface>hardware_interface/PositionJointInterface</hardwareInterface>
      <mechanicalReduction>1</mechanicalReduction>
    </actuator>
  </transmission>
  <!-- Transmission 4 -->
  <transmission name="tran4">
    <type>transmission_interface/SimpleTransmission</type>
    <joint name="joint4">
      <hardwareInterface>hardware_interface/PositionJointInterface</hardwareInterface>
    </joint>
    <actuator name="motor4">
      <hardwareInterface>hardware_interface/PositionJointInterface</hardwareInterface>
      <mechanicalReduction>1</mechanicalReduction>
    </actuator>
  </transmission>
  <!-- Transmission 5 -->
  <transmission name="tran5">
    <type>transmission_interface/SimpleTransmission</type>
    <joint name="joint5">
      <hardwareInterface>hardware_interface/PositionJointInterface</hardwareInterface>
    </joint>
    <actuator name="motor5">
      <hardwareInterface>hardware_interface/PositionJointInterface</hardwareInterface>
      <mechanicalReduction>1</mechanicalReduction>
    </actuator>
  </transmission>
  <!-- Transmission 6 -->
  <transmission name="tran6">
    <type>transmission_interface/SimpleTransmission</type>
    <joint name="joint6">
      <hardwareInterface>hardware_interface/PositionJointInterface</hardwareInterface>
    </joint>
    <actuator name="motor6">
      <hardwareInterface>hardware_interface/PositionJointInterface</hardwareInterface>
      <mechanicalReduction>1</mechanicalReduction>
    </actuator>
  </transmission>
  <!-- ros_control plugin -->
  <gazebo>
    <plugin filename="ign_ros2_control-system" name="ign_ros2_control::IgnitionROS2ControlPlugin">
      <ros>
        <namespace>dsr01</namespace>
      </ros>
      <parameters>/root/doosan_robot/install/dsr_controller2/share/dsr_controller2/config/dsr_controller2_gz.yaml</parameters>
    </plugin>
  </gazebo>
  <!-- Base -->
  <gazebo reference="dsr01base_0">
    <kp>100000.0</kp>
    <kd>100.0</kd>
    <mu1>30.0</mu1>
    <mu2>30.0</mu2>
    <maxVel>1.0</maxVel>
    <minDepth>0.001</minDepth>
  </gazebo>
  <!-- Link1 -->
  <gazebo reference="dsr01link1">
    <kp>100000.0</kp>
    <kd>100.0</kd>
    <mu1>30.0</mu1>
    <mu2>30.0</mu2>
    <maxVel>1.0</maxVel>
    <minDepth>0.001</minDepth>
  </gazebo>
  <!-- Link2 -->
  <gazebo reference="dsr01link2">
    <kp>100000.0</kp>
    <kd>100.0</kd>
    <mu1>30.0</mu1>
    <mu2>30.0</mu2>
    <maxVel>1.0</maxVel>
    <minDepth>0.001</minDepth>
  </gazebo>
  <!-- Link3 -->
  <gazebo reference="dsr01link3">
    <kp>100000.0</kp>
    <kd>100.0</kd>
    <mu1>30.0</mu1>
    <mu2>30.0</mu2>
    <maxVel>1.0</maxVel>
    <minDepth>0.001</minDepth>
  </gazebo>
  <!-- Link4 -->
  <gazebo reference="dsr01link4">
    <kp>100000.0</kp>
    <kd>100.0</kd>
    <mu1>30.0</mu1>
    <mu2>30.0</mu2>
    <maxVel>1.0</maxVel>
    <minDepth>0.001</minDepth>
  </gazebo>
  <!-- Link5 -->
  <gazebo reference="dsr01link5">
    <kp>100000.0</kp>
    <kd>100.0</kd>
    <mu1>30.0</mu1>
    <mu2>30.0</mu2>
    <maxVel>1.0</maxVel>
    <minDepth>0.001</minDepth>
  </gazebo>
  <!-- Link6 -->
  <gazebo reference="dsr01link6">
    <kp>100000.0</kp>
    <kd>100.0</kd>
    <mu1>30.0</mu1>
    <mu2>30.0</mu2>
    <maxVel>1.0</maxVel>
    <minDepth>0.001</minDepth>
  </gazebo>
</robot>
